Traceback (most recent call last):
  File "/home/wsi-server/.local/lib/python3.8/site-packages/urllib3/connection.py", line 174, in _new_conn
    conn = connection.create_connection(
  File "/home/wsi-server/.local/lib/python3.8/site-packages/urllib3/util/connection.py", line 96, in create_connection
    raise err
  File "/home/wsi-server/.local/lib/python3.8/site-packages/urllib3/util/connection.py", line 86, in create_connection
    sock.connect(sa)
OSError: [Errno 113] No route to host

During handling of the above exception, another exception occurred:

Traceback (most recent call last):
  File "/home/wsi-server/.local/lib/python3.8/site-packages/urllib3/connectionpool.py", line 699, in urlopen
    httplib_response = self._make_request(
  File "/home/wsi-server/.local/lib/python3.8/site-packages/urllib3/connectionpool.py", line 394, in _make_request
    conn.request(method, url, **httplib_request_kw)
  File "/home/wsi-server/.local/lib/python3.8/site-packages/urllib3/connection.py", line 239, in request
    super(HTTPConnection, self).request(method, url, body=body, headers=headers)
  File "/usr/lib/python3.8/http/client.py", line 1252, in request
    self._send_request(method, url, body, headers, encode_chunked)
  File "/usr/lib/python3.8/http/client.py", line 1298, in _send_request
    self.endheaders(body, encode_chunked=encode_chunked)
  File "/usr/lib/python3.8/http/client.py", line 1247, in endheaders
    self._send_output(message_body, encode_chunked=encode_chunked)
  File "/usr/lib/python3.8/http/client.py", line 1007, in _send_output
    self.send(msg)
  File "/usr/lib/python3.8/http/client.py", line 947, in send
    self.connect()
  File "/home/wsi-server/.local/lib/python3.8/site-packages/urllib3/connection.py", line 205, in connect
    conn = self._new_conn()
  File "/home/wsi-server/.local/lib/python3.8/site-packages/urllib3/connection.py", line 186, in _new_conn
    raise NewConnectionError(
urllib3.exceptions.NewConnectionError: <urllib3.connection.HTTPConnection object at 0x7f94ecec8a00>: Failed to establish a new connection: [Errno 113] No route to host

During handling of the above exception, another exception occurred:

Traceback (most recent call last):
  File "/home/wsi-server/.local/lib/python3.8/site-packages/requests/adapters.py", line 439, in send
    resp = conn.urlopen(
  File "/home/wsi-server/.local/lib/python3.8/site-packages/urllib3/connectionpool.py", line 755, in urlopen
    retries = retries.increment(
  File "/home/wsi-server/.local/lib/python3.8/site-packages/urllib3/util/retry.py", line 574, in increment
    raise MaxRetryError(_pool, url, error or ResponseError(cause))
urllib3.exceptions.MaxRetryError: HTTPConnectionPool(host='202.90.198.127', port=80): Max retries exceeded with url: /esdxsta/log/alor.php (Caused by NewConnectionError('<urllib3.connection.HTTPConnection object at 0x7f94ecec8a00>: Failed to establish a new connection: [Errno 113] No route to host'))

During handling of the above exception, another exception occurred:

Traceback (most recent call last):
  File "esdx.py", line 34, in <module>
    page = requests.get(detilSta[1])
  File "/home/wsi-server/.local/lib/python3.8/site-packages/requests/api.py", line 75, in get
    return request('get', url, params=params, **kwargs)
  File "/home/wsi-server/.local/lib/python3.8/site-packages/requests/api.py", line 61, in request
    return session.request(method=method, url=url, **kwargs)
  File "/home/wsi-server/.local/lib/python3.8/site-packages/requests/sessions.py", line 542, in request
    resp = self.send(prep, **send_kwargs)
  File "/home/wsi-server/.local/lib/python3.8/site-packages/requests/sessions.py", line 655, in send
    r = adapter.send(request, **kwargs)
  File "/home/wsi-server/.local/lib/python3.8/site-packages/requests/adapters.py", line 516, in send
    raise ConnectionError(e, request=request)
requests.exceptions.ConnectionError: HTTPConnectionPool(host='202.90.198.127', port=80): Max retries exceeded with url: /esdxsta/log/alor.php (Caused by NewConnectionError('<urllib3.connection.HTTPConnection object at 0x7f94ecec8a00>: Failed to establish a new connection: [Errno 113] No route to host'))

Error bro  jam 2021-12-14 04:05:05.156359
Error bro  jam 2021-12-14 06:34:27.253738
Error bro  jam 2021-12-14 08:55:02.276736
Error bro  jam 2021-12-14 10:41:02.430330
Error bro  jam 2021-12-14 16:04:52.623042
Error bro  jam 2021-12-14 17:50:00.444369
Error bro  jam 2021-12-14 19:43:05.703225
Error bro  jam 2021-12-15 01:37:50.648725
Error bro  jam 2021-12-15 05:39:53.977029
Error bro  jam 2021-12-15 09:39:03.304763